Workbook

Sheet 00 Read Me
A1: Enterprise Architecture Project Impact Matrix
A2: <client or portfolio name> | Version 1.0 | <date>
A4: Purpose
A5: Scores each proposed initiative on a consistent set of weighted dimensions so that sequencing and funding decisions can be defended in an EA forum.
A6: Replace this text with the specific purpose for this engagement.
A7: Every score is a starting position for review, not a decision.
A9: Sheets
A10: Sheet | B10: What it is for | C10: Who maintains it | D10: Update cadence
A11: 01 Scoring Model | B11: Weights and the 1 to 5 anchors. Change a weight and every project score recalculates. | C11: Enterprise Architecture | D11: At each portfolio review
A12: 02 Portfolio Summary | B12: Roll-up with weighted score, rank, cost and score per $100k. The board view. | C12: Enterprise Architecture | D12: Automatic
A13: 03 Sequencing | B13: Waves, cross-project dependencies, and resource contention. | C13: EA and Delivery | D13: At each portfolio review
A14: 04 Risk Register | B14: All project risks with likelihood, impact and mitigation. | C14: Enterprise Architecture | D14: Fortnightly
A15: 05 Open Questions | B15: What must be answered before approval, and the decision each blocks. | C15: Engagement lead | D15: Weekly until closed
A16: 06 Savings Case | B16: Payback model. Fill the baseline and expected saving; payback calculates. | C16: FinOps and EA | D16: Monthly
A17: 07 Decision Log | B17: What the forum decided, on what conditions, and who answers for it. | C17: EA and Delivery | D17: After each forum
A18: P1 to P8 | B18: One sheet per initiative. Delete the slots you do not use. | C18: Project architect | D18: Weekly during delivery
A20: Cell conventions
A21: Blue text | B21: Hardcoded input. Edit these.
A22: Green text | B22: Link pulled from another sheet. Do not overwrite.
A23: Black text | B23: Calculated. Do not overwrite.
A24: Yellow fill | B24: Information still owed. These are the gaps that block approval.
A26: Rules that keep this useful
A27: Never give two initiatives the same score profile. If they score the same on every dimension, the matrix cannot rank them and has no decision value. This is the single most common failure mode.
A28: Score against evidence, and cite the source document and section in the evidence column. A score of 3 with a named source beats a score of 5 with none.
A29: Where no evidence exists, score conservatively and log the gap on '05 Open Questions'. Do not guess upward.
A30: A score can be deliberately low where a proposal is weaker than it claims. Those are the most valuable cells in the workbook.
A31: Set the weights to the prioritization lens the sponsor confirms, before scoring. Do not score first and pick the lens that gives the answer you wanted.
A32: Owners are people, not roles. 'Security' does not approve anything; a named individual does.
A34: Governance record
A35: Prioritization lens | B35: balanced | C35: Confirmed with the sponsor before scoring.
A36: Lens agreed by (named) | B36: A. Example, VP Operations | C36: The person who accepted these weights.
A37: Lens agreed on | B37: 2026-01-15
A38: Risk appetite | B38: No red risk without a named owner and a review date. | C38: Red risks start at a score of 9.
A39: Next review | B39: 2026-04-15 | C39: Re-score on a material change, or on this date.
A40: Terms follow TOGAF and COBIT: an initiative is a work package, a wave is a transition architecture. See references/standards-mapping.md.
A42: Document coverage
A43: Document | B43: What it feeds in this workbook | C43: Level | D43: Coverage
A44: Proposal, business case or statement of work (PROPOSAL) | B44: Project profile (name, sponsor, scope, deadline, status, basis); Business value and Cost assessments; the questions the proposal asks the client go to 05 Open Questions | C44: Required, each initiative | D44: Received for all scored initiatives
A45: Cost and effort estimate: line items, hours by role, duration (ESTIMATE) | B45: Cost and duration cells, score per $100k on 02 Portfolio Summary, capacity on 03 Sequencing, Delivery confidence | C45: Required, each initiative | D45: Received for all scored initiatives
A46: Target-state architecture, principles and strategy (TARGET_STATE) | B46: Strategic alignment score, section 9 (capability, principles, gap closed), gates 1 and 2 | C46: Required, portfolio | D46: Received
...

Sheet 01 Scoring Model
A1: Scoring model
A2: Lens: balanced. Changing a weight recalculates every project sheet and the summary.
A4: Weights
A5: Dimension | B5: Weight | C5: Rationale
A6: Business value | B6: 0.2 | C6: Whether the initiative changes a business outcome, not just a technical one.
A7: Cost optimization and savings | B7: 0.2 | C7: Direct savings and the ability to evidence savings. An unevidenced saving cannot be booked.
A8: Time criticality | B8: 0.2 | C8: Deadlines, vendor retirements, and problems that cost something every month they wait.
A9: Risk reduction and resilience | B9: 0.1 | C9: Reduction in incident frequency, blast radius, or single points of failure.
A10: Security and compliance | B10: 0.1 | C10: Net change in security posture. This can be negative.
A11: Delivery confidence | B11: 0.1 | C11: Confidence the work lands on time and scope. Low confidence discounts a high score.
A12: Strategic and architecture alignment | B12: 0.1 | C12: Whether it advances a target-state standard or is purely tactical.
A13: Total | B13: =SUM(B6:B12) -> 1 | C13: Must equal 100 percent.
A15: Lens presets
A16: Preset | B16: Business value | C16: Cost optimization and savings | D16: Time criticality | E16: Risk reduction and resilience | F16: Security and compliance | G16: Delivery confidence | H16: Strategic and architecture alignment
A17: balanced | B17: 0.2 | C17: 0.2 | D17: 0.2 | E17: 0.1 | F17: 0.1 | G17: 0.1 | H17: 0.1
A18: run_cost | B18: 0.1 | C18: 0.35 | D18: 0.15 | E18: 0.1 | F18: 0.05 | G18: 0.15 | H18: 0.1
A19: deadline_risk | B19: 0.1 | C19: 0.1 | D19: 0.35 | E19: 0.2 | F19: 0.05 | G19: 0.1 | H19: 0.1
A20: delivery_speed | B20: 0.15 | C20: 0.1 | D20: 0.15 | E20: 0.1 | F20: 0.05 | G20: 0.35 | H20: 0.1
A21: security | B21: 0.1 | C21: 0.1 | D21: 0.1 | E21: 0.2 | F21: 0.35 | G21: 0.05 | H21: 0.1
A23: Copy a preset row into B6:B12 to switch lens. Confirm the lens with the sponsor before scoring, not after.
A25: Score anchors, 1 to 5
A26: Dimension | C26: 1 | D26: 2 | E26: 3 | F26: 4 | G26: 5
A27: Business value | C27: No measurable business outcome; internal convenience only. | D27: Efficiency gain for one team, no quantified baseline. | E27: Quantified efficiency or quality gain for a defined process. | F27: Removes a live operational blind spot or unlocks decisions across teams. | G27: Direct revenue, contractual, or client-facing outcome.
A28: Cost optimization and savings | C28: No savings; adds run cost. | D28: Soft labour savings only, not booked. | E28: Modest run-cost reduction, single digit percent of the affected spend. | F28: Material and measurable reduction, or a direct enabler of one. | G28: Primary purpose is cost reduction with a named savings target.
A29: Time criticality | C29: No deadline. Can slip a year with no consequence. | D29: Preferable this year, no consequence if deferred. | E29: A live problem is costing time or risk every month it waits. | F29: Dependency window or vendor change makes deferral expensive. | G29: Hard external deadline or an already unsupported component.
A30: Risk reduction and resilience | C30: No change to risk posture. | D30: Marginal improvement. | E30: Reduces the frequency or blast radius of a known failure mode. | F30: Removes a recurring incident cause or restores a lost safety net. | G30: Removes a single point of failure with client-visible consequences.
A31: Security and compliance | C31: Increases attack surface with no offsetting control. | D31: Net neutral, or new surface offset by new controls. | E31: Minor control improvement. | F31: Removes standing credentials, adds auditability or least privilege. | G31: Closes an audit or regulatory finding.
A32: Delivery confidence | C32: Novel, undefined scope, unproven pattern, external dependency. | D32: Large scope with material unknowns. | E32: Well understood work with normal coordination overhead. | F32: Proven pattern already running elsewhere in the estate. | G32: Small, bounded, single team, reversible in hours.
A33: Strategic and architecture alignment | C33: Conflicts with target-state architecture. | D33: Tactical, creates no reusable asset. | E33: Consistent with standards, no reuse beyond itself. | F33: Advances a target-state standard reusable by other workloads. | G33: Establishes or completes an enterprise standard.

Sheet 02 Portfolio Summary
A1: Portfolio summary
A2: Everything pulls from the project sheets. Weights come from '01 Scoring Model'.
A4: Ranked portfolio
A5: ID | B5: Project | C5: Estimated cost (USD) | D5: Duration (months) | E5: Weighted score | F5: Rank | G5: Score per $100k | H5: Time criticality | I5: Delivery confidence | J5: Cost optimization | K5: Recommended wave
A6: P1 | B6: =IF('P1'!B6="","",'P1'!B6) -> EXAMPLE Replace nightly batch export with event streaming | C6: =IF('P1'!B10="","",'P1'!B10) -> 84000 | D6: =IF('P1'!B11="","",'P1'!B11) -> 3 | E6: ='P1'!$D$27 -> 3.5 | F6: =IF(E6="","",RANK(E6,$E$6:$E$13)) -> 1 | G6: =IFERROR(E6/(C6/100000),"") -> 4.1666667 | H6: =IF('P1'!$B$22="","",'P1'!$B$22) -> 3 | I6: =IF('P1'!$B$25="","",'P1'!$B$25) -> 4 | J6: =IF('P1'!$B$21="","",'P1'!$B$21) -> 3 | K6: =IF('P1'!B14="","",'P1'!B14) -> Wave 1
A7: P2 | B7: =IF('P2'!B6="","",'P2'!B6) | C7: =IF('P2'!B10="","",'P2'!B10) -> 0 | D7: =IF('P2'!B11="","",'P2'!B11) -> 0 | E7: ='P2'!$D$27 | F7: =IF(E7="","",RANK(E7,$E$6:$E$13)) | G7: =IFERROR(E7/(C7/100000),"") | H7: =IF('P2'!$B$22="","",'P2'!$B$22) | I7: =IF('P2'!$B$25="","",'P2'!$B$25) | J7: =IF('P2'!$B$21="","",'P2'!$B$21) | K7: =IF('P2'!B14="","",'P2'!B14)
A8: P3 | B8: =IF('P3'!B6="","",'P3'!B6) | C8: =IF('P3'!B10="","",'P3'!B10) -> 0 | D8: =IF('P3'!B11="","",'P3'!B11) -> 0 | E8: ='P3'!$D$27 | F8: =IF(E8="","",RANK(E8,$E$6:$E$13)) | G8: =IFERROR(E8/(C8/100000),"") | H8: =IF('P3'!$B$22="","",'P3'!$B$22) | I8: =IF('P3'!$B$25="","",'P3'!$B$25) | J8: =IF('P3'!$B$21="","",'P3'!$B$21) | K8: =IF('P3'!B14="","",'P3'!B14)
A9: P4 | B9: =IF('P4'!B6="","",'P4'!B6) | C9: =IF('P4'!B10="","",'P4'!B10) -> 0 | D9: =IF('P4'!B11="","",'P4'!B11) -> 0 | E9: ='P4'!$D$27 | F9: =IF(E9="","",RANK(E9,$E$6:$E$13)) | G9: =IFERROR(E9/(C9/100000),"") | H9: =IF('P4'!$B$22="","",'P4'!$B$22) | I9: =IF('P4'!$B$25="","",'P4'!$B$25) | J9: =IF('P4'!$B$21="","",'P4'!$B$21) | K9: =IF('P4'!B14="","",'P4'!B14)
A10: P5 | B10: =IF('P5'!B6="","",'P5'!B6) | C10: =IF('P5'!B10="","",'P5'!B10) -> 0 | D10: =IF('P5'!B11="","",'P5'!B11) -> 0 | E10: ='P5'!$D$27 | F10: =IF(E10="","",RANK(E10,$E$6:$E$13)) | G10: =IFERROR(E10/(C10/100000),"") | H10: =IF('P5'!$B$22="","",'P5'!$B$22) | I10: =IF('P5'!$B$25="","",'P5'!$B$25) | J10: =IF('P5'!$B$21="","",'P5'!$B$21) | K10: =IF('P5'!B14="","",'P5'!B14)
A11: P6 | B11: =IF('P6'!B6="","",'P6'!B6) | C11: =IF('P6'!B10="","",'P6'!B10) -> 0 | D11: =IF('P6'!B11="","",'P6'!B11) -> 0 | E11: ='P6'!$D$27 | F11: =IF(E11="","",RANK(E11,$E$6:$E$13)) | G11: =IFERROR(E11/(C11/100000),"") | H11: =IF('P6'!$B$22="","",'P6'!$B$22) | I11: =IF('P6'!$B$25="","",'P6'!$B$25) | J11: =IF('P6'!$B$21="","",'P6'!$B$21) | K11: =IF('P6'!B14="","",'P6'!B14)
A12: P7 | B12: =IF('P7'!B6="","",'P7'!B6) | C12: =IF('P7'!B10="","",'P7'!B10) -> 0 | D12: =IF('P7'!B11="","",'P7'!B11) -> 0 | E12: ='P7'!$D$27 | F12: =IF(E12="","",RANK(E12,$E$6:$E$13)) | G12: =IFERROR(E12/(C12/100000),"") | H12: =IF('P7'!$B$22="","",'P7'!$B$22) | I12: =IF('P7'!$B$25="","",'P7'!$B$25) | J12: =IF('P7'!$B$21="","",'P7'!$B$21) | K12: =IF('P7'!B14="","",'P7'!B14)
A13: P8 | B13: =IF('P8'!B6="","",'P8'!B6) | C13: =IF('P8'!B10="","",'P8'!B10) -> 0 | D13: =IF('P8'!B11="","",'P8'!B11) -> 0 | E13: ='P8'!$D$27 | F13: =IF(E13="","",RANK(E13,$E$6:$E$13)) | G13: =IFERROR(E13/(C13/100000),"") | H13: =IF('P8'!$B$22="","",'P8'!$B$22) | I13: =IF('P8'!$B$25="","",'P8'!$B$25) | J13: =IF('P8'!$B$21="","",'P8'!$B$21) | K13: =IF('P8'!B14="","",'P8'!B14)
B14: Portfolio | C14: =SUM(C6:C13) -> 84000 | E14: =IFERROR(AVERAGE(E6:E13),"") -> 3.5
A17: How to read this
A18: Weighted score answers how much this matters. Score per $100k answers how much we get for the money.
A19: Replace these lines with the specific reading for this portfolio, naming initiatives.

Sheet 03 Sequencing
A1: Sequencing, dependencies and capacity
A2: Recommended delivery order and the constraints that shape it
A4: Recommended waves
A5: Wave | B5: Projects | C5: Indicative window | D5: Cost (USD) | E5: Why this grouping | F5: Entry condition
A6: Wave 1 | B6: <initiatives> | C6: <window> | D6: 0 | E6: <why this grouping> | F6: <entry condition>
A7: Wave 2 | D7: 0
A8: Wave 3 | D8: 0
A9: Hold | C9: Not scheduled | D9: 0 | E9: <why held rather than dropped> | F9: <what would unhold it>
B10: Total | D10: =SUM(D6:D9) -> 0
A12: Cross-project dependencies
A13: From | B13: To | C13: Type | D13: Strength | E13: What it means for sequencing | F13: Owner
A21: Resource contention
A22: Role | B22: Committed across the portfolio | C22: Peak concurrent demand | E22: Constraint
A23: Solutions Architect
A24: DevOps / Platform Engineer
A25: Project Manager
A26: FinOps

Sheet 04 Risk Register
A1: Consolidated risk register
A2: All project risks, ranked by initial likelihood times impact
A4: Risks across the portfolio
A5: ID | B5: Project | C5: Risk | D5: Likelihood | E5: Impact | F5: Score | G5: Mitigation | H5: Owner | I5: Response | J5: Residual
A6: R01 | B6: P1 | C6: Duplicate or lost records during parallel run | D6: Medium | E6: Critical | F6: 8 | G6: Run both paths against a shadow consumer group and reconcile record counts daily before cutover. | H6: Architecture | I6: Mitigate | J6: 3
A7: R02 | B7: P1 | C7: Event Hubs throughput unit cost not modelled | D7: High | E7: Medium | F7: 6 | G7: Model expected events per second against the pricing tier before committing. | H7: FinOps | I7: Mitigate | J7: 2
A8: R03 | B8: P1 | C8: Downstream consumers assume a nightly batch boundary | D8: Medium | E8: High | F8: 6 | G8: Survey each consumer for time-window assumptions during design. | H8: PM
A9: R04 | B9: P1 | C9: Batch VM decommission deferred indefinitely, so no saving lands | D9: High | E9: Medium | F9: 6 | G9: Make the decommission a named deliverable with a date, not a follow-up. | H9: Delivery lead
A11: Score is likelihood times impact, each 1 to 4 (Low, Medium, High, Critical). Red at 9 or above, amber from 6. Every red risk needs a named owner and a review date before its project is approved. Response is Mitigate, Accept, Transfer or Avoid. Residual is the score once the mitigation is in place.

Sheet 05 Open Questions
A1: Open questions and information gaps
A2: What is still owed, and the decision each answer unblocks
A4: Blocking questions, in priority order
A5: ID | B5: Project | C5: Area | D5: Question | E5: Why it matters and what it unblocks | F5: Owner to answer | G5: Status
A6: Q01 | G6: Open
A7: Q02 | G7: Open
A8: Q03 | G8: Open
A9: Q04 | G9: Open
A10: Q05 | G10: Open
A11: Q06 | G11: Open
A12: Q07 | G12: Open
A13: Q08 | G13: Open
A14: Q09 | G14: Open
A15: Q10 | G15: Open
A16: Q11 | G16: Open
A17: Q12 | G17: Open
... A19: Q14 | G19: Open

Sheet 06 Savings Case
A1: Savings case and payback
A2: Yellow cells are the inputs still owed. Everything else calculates.
A4: Payback model
A5: ID | B5: Project | C5: Build cost (USD) | D5: Current annual run cost (USD) | E5: Expected annual saving (USD) | F5: Saving % | G5: Payback (months) | H5: Evidence position
A6: P1 | B6: =IF('P1'!B6="","",'P1'!B6) -> EXAMPLE Replace nightly batch export with event streaming | C6: ='P1'!B10 -> 84000 | D6: 0 | E6: 0 | F6: =IFERROR(E6/D6,"") | G6: =IFERROR(C6/(E6/12),"Awaiting baseline") -> Awaiting baseline | H6: EXAMPLE. Fill D and E once the baseline arrives. Payback calculates.
A7: P2 | B7: =IF('P2'!B6="","",'P2'!B6) | C7: ='P2'!B10 -> 0 | D7: 0 | E7: 0 | F7: =IFERROR(E7/D7,"") | G7: =IFERROR(C7/(E7/12),"Awaiting baseline") -> Awaiting baseline
A8: P3 | B8: =IF('P3'!B6="","",'P3'!B6) | C8: ='P3'!B10 -> 0 | D8: 0 | E8: 0 | F8: =IFERROR(E8/D8,"") | G8: =IFERROR(C8/(E8/12),"Awaiting baseline") -> Awaiting baseline
A9: P4 | B9: =IF('P4'!B6="","",'P4'!B6) | C9: ='P4'!B10 -> 0 | D9: 0 | E9: 0 | F9: =IFERROR(E9/D9,"") | G9: =IFERROR(C9/(E9/12),"Awaiting baseline") -> Awaiting baseline
A10: P5 | B10: =IF('P5'!B6="","",'P5'!B6) | C10: ='P5'!B10 -> 0 | D10: 0 | E10: 0 | F10: =IFERROR(E10/D10,"") | G10: =IFERROR(C10/(E10/12),"Awaiting baseline") -> Awaiting baseline
A11: P6 | B11: =IF('P6'!B6="","",'P6'!B6) | C11: ='P6'!B10 -> 0 | D11: 0 | E11: 0 | F11: =IFERROR(E11/D11,"") | G11: =IFERROR(C11/(E11/12),"Awaiting baseline") -> Awaiting baseline
A12: P7 | B12: =IF('P7'!B6="","",'P7'!B6) | C12: ='P7'!B10 -> 0 | D12: 0 | E12: 0 | F12: =IFERROR(E12/D12,"") | G12: =IFERROR(C12/(E12/12),"Awaiting baseline") -> Awaiting baseline
A13: P8 | B13: =IF('P8'!B6="","",'P8'!B6) | C13: ='P8'!B10 -> 0 | D13: 0 | E13: 0 | F13: =IFERROR(E13/D13,"") | G13: =IFERROR(C13/(E13/12),"Awaiting baseline") -> Awaiting baseline
B14: Portfolio | C14: =SUM(C6:C13) -> 84000 | D14: =SUM(D6:D13) -> 0 | E14: =SUM(E6:E13) -> 0 | F14: =IFERROR(E14/D14,"") | G14: =IFERROR(C14/(E14/12),"Awaiting baseline") -> Awaiting baseline
A16: Columns D and E are the only inputs. An initiative that is a pure enabler should show zero expected saving and be argued on the grounds that it makes the other rows provable.

Sheet 07 Decision Log
A1: Decision log
A2: What the forum decided, on what conditions, and who answers for it
A4: Decisions
A5: Ref | B5: Project | C5: Decision | D5: Conditions and rationale | E5: Decided by (named) | F5: Date | G5: Reference (ADR or minutes)
A17: Decisions: Approved, Approved with conditions, Deferred, Held, Rejected. A deferred or held initiative states what would change the decision. The scores recommend; this sheet records what was decided.

Sheet P1
A1: P1. EXAMPLE Replace nightly batch export with event streaming
A2: Enterprise Architecture Impact Matrix
A4: 1. Project profile
A5: Project ID | B5: P1
A6: Project name | B6: EXAMPLE Replace nightly batch export with event streaming | E6: Pulled by '02 Portfolio Summary'. Keep it in this cell.
A7: Business sponsor | B7: A. Example, VP Operations | E7: Named individual required before EA approval.
A8: Architecture owner | B8: B. Example, Cloud Architect | E8: Named individual required before EA approval.
A9: Delivery owner | B9: C. Example, Delivery Lead | E9: Named individual required before EA approval.
A10: Estimated cost (USD) | B10: 84000 | E10: Proposal deck slide 14. Line items sum correctly.
A11: Estimated duration (months) | B11: 3 | E11: 3 months, two engineers plus part-time architect.
A12: Hard external deadline | B12: None contractual. The nightly window is already overrunning twice a week.
A13: Current status | B13: Proposed, awaiting approval
A14: Recommended wave | B14: Wave 1 | E14: See '03 Sequencing'.
A15: Basis of estimate | B15: Proposal deck slides 6 and 14; batch failure log Jan to Jun 2026. | E15: Cite the document and slide or section.
A17: 2. Weighted impact assessment
A18: Enter 1 to 5 in column B. Anchors are on '01 Scoring Model'. Column C is a link; do not edit it.
A19: Dimension | B19: Score (1-5) | C19: Weight | D19: Weighted | E19: Assessment | F19: Owner | G19: Evidence and basis
A20: Business value | B20: 4 | C20: ='01 Scoring Model'!$B$6 -> 0.2 | D20: =IF(B20="","",B20*C20) -> 0.8 | E20: Downstream teams currently wait until 06:00 for data that is generated continuously. Removing the wait changes when decisions can be made, not just how fast a job runs. | F20: A. Example | G20: Deck slide 6; batch completion times Jan to Jun.
A21: Cost optimization and savings | B21: 3 | C21: ='01 Scoring Model'!$B$7 -> 0.2 | D21: =IF(B21="","",B21*C21) -> 0.6 | E21: Removes an always-on batch VM but adds Event Hubs throughput units. Net saving is real but modest and needs modelling before it is claimed. | F21: FinOps | G21: Deck slide 14. Throughput unit cost not in the estimate.
A22: Time criticality | B22: 3 | C22: ='01 Scoring Model'!$B$8 -> 0.2 | D22: =IF(B22="","",B22*C22) -> 0.6 | E22: No deadline, but the nightly window overruns twice a week and the failure rate is trending up. | F22: Platform Team | G22: Batch failure log Jan to Jun 2026.
A23: Risk reduction and resilience | B23: 4 | C23: ='01 Scoring Model'!$B$9 -> 0.1 | D23: =IF(B23="","",B23*C23) -> 0.4 | E23: Removes a single nightly failure point that currently takes the whole downstream chain with it. | F23: Platform Team | G23: Incident records, 6 occurrences in H1.
A24: Security and compliance | B24: 3 | C24: ='01 Scoring Model'!$B$10 -> 0.1 | D24: =IF(B24="","",B24*C24) -> 0.3 | E24: Replaces a shared service account with managed identity. Modest control improvement. | F24: Security | G24: Current-state review, section 4.
A25: Delivery confidence | B25: 4 | C25: ='01 Scoring Model'!$B$11 -> 0.1 | D25: =IF(B25="","",B25*C25) -> 0.4 | E25: The same pattern is already in production for a smaller feed, so this reuses a proven design. | F25: Architecture | G25: Existing implementation on the orders feed.
A26: Strategic and architecture alignment | B26: 4 | C26: ='01 Scoring Model'!$B$12 -> 0.1 | D26: =IF(B26="","",B26*C26) -> 0.4 | E26: Advances the event-driven target state and creates a pattern other feeds can reuse. | F26: Architecture | G26: Target-state architecture, section 3.
A27: Weighted priority score | D27: =IF(COUNT(B20:B26)=0,"",ROUND(SUM(D20:D26),2)) -> 3.5 | E27: Out of 5.00. Compare on '02 Portfolio Summary'.
A29: 3. Scope
A30: In scope | E30: Explicitly out of scope
A31: Event Hubs ingestion for the customer feed | E31: Other feeds beyond the customer feed
A32: Consumer rewrite with idempotent handling | E32: Downstream consumer redesign
A33: Parallel run against the existing batch | E33: Data model changes
A34: Runbook and alert updates | E34: Decommission of the batch VM (separate change)
A36: 4. Dependencies
A37: Type | B37: Depends on | E37: Nature of the dependency | F37: Owner | G37: Criticality
A38: Platform | B38: Existing Event Hubs namespace | E38: Reuse, do not recreate. Upstream diagnostic settings point at it. | F38: Platform Team | G38: Critical
A39: Client team | B39: Downstream data owners | E39: They must confirm parity before the batch is switched off. | F39: PM | G39: High
A40: Internal | B40: P2 Cost visibility work | E40: Supplies the run-cost baseline this project's saving is measured against. | F40: FinOps | G40: Medium
A41: Resource | B41: Solutions Architect capacity | E41: Part time for 3 months. Check against other initiatives. | F41: Delivery lead | G41: Medium
A43: 5. Key risks
A44: Risk | B44: Likelihood | C44: Impact | D44: Score | E44: Mitigation | F44: Owner | G44: Response (residual score)
A45: Duplicate or lost records during parallel run | B45: Medium | C45: Critical | D45: 8 | E45: Run both paths against a shadow consumer group and reconcile record counts daily before cutover. | F45: Architecture | G45: Mitigate (residual 3)
...

Sheet P2
A1: P2. <project name>
A2: Enterprise Architecture Impact Matrix
A4: 1. Project profile
A5: Project ID | B5: P2
A6: Project name | E6: Pulled by '02 Portfolio Summary'. Keep it in this cell.
A7: Business sponsor | B7: TBC | E7: Named individual required before EA approval.
A8: Architecture owner | B8: TBC | E8: Named individual required before EA approval.
A9: Delivery owner | B9: TBC | E9: Named individual required before EA approval.
A10: Estimated cost (USD) | B10: 0
A11: Estimated duration (months) | B11: 0
A12: Hard external deadline
A13: Current status | B13: Proposed
A14: Recommended wave | E14: See '03 Sequencing'.
A15: Basis of estimate | B15: TBC | E15: Cite the document and slide or section.
A17: 2. Weighted impact assessment
A18: Enter 1 to 5 in column B. Anchors are on '01 Scoring Model'. Column C is a link; do not edit it.
A19: Dimension | B19: Score (1-5) | C19: Weight | D19: Weighted | E19: Assessment | F19: Owner | G19: Evidence and basis
A20: Business value | C20: ='01 Scoring Model'!$B$6 -> 0.2 | D20: =IF(B20="","",B20*C20)
A21: Cost optimization and savings | C21: ='01 Scoring Model'!$B$7 -> 0.2 | D21: =IF(B21="","",B21*C21)
A22: Time criticality | C22: ='01 Scoring Model'!$B$8 -> 0.2 | D22: =IF(B22="","",B22*C22)
A23: Risk reduction and resilience | C23: ='01 Scoring Model'!$B$9 -> 0.1 | D23: =IF(B23="","",B23*C23)
A24: Security and compliance | C24: ='01 Scoring Model'!$B$10 -> 0.1 | D24: =IF(B24="","",B24*C24)
A25: Delivery confidence | C25: ='01 Scoring Model'!$B$11 -> 0.1 | D25: =IF(B25="","",B25*C25)
A26: Strategic and architecture alignment | C26: ='01 Scoring Model'!$B$12 -> 0.1 | D26: =IF(B26="","",B26*C26)
A27: Weighted priority score | D27: =IF(COUNT(B20:B26)=0,"",ROUND(SUM(D20:D26),2)) | E27: Out of 5.00. Compare on '02 Portfolio Summary'.
A29: 3. Scope
A30: In scope | E30: Explicitly out of scope
A36: 4. Dependencies
A37: Type | B37: Depends on | E37: Nature of the dependency | F37: Owner | G37: Criticality
A43: 5. Key risks
A44: Risk | B44: Likelihood | C44: Impact | D44: Score | E44: Mitigation | F44: Owner | G44: Response (residual score)
A49: Likelihood times impact, each 1 to 4 (Low, Medium, High, Critical). Red at 9 or above: needs a named owner and a review date. Optional 6th to 8th items per risk: response, residual likelihood, residual impact.
A51: 6. Success KPIs
A52: KPI | B52: Baseline | D52: Target | E52: Measurement source | F52: Measured by
A58: 7. EA governance gates
A59: Gate | B59: Status | E59: Evidence or artefact | F59: Reviewer | G59: Date cleared
A60: Alignment with a named business capability | B60: Not started
A61: Architecture standards compliance | B61: Not started
A62: Security review completed | B62: Not started
A63: Operational ownership defined (named team, not a role) | B63: Not started
...

Sheet P3
A1: P3. <project name>
A2: Enterprise Architecture Impact Matrix
A4: 1. Project profile
A5: Project ID | B5: P3
A6: Project name | E6: Pulled by '02 Portfolio Summary'. Keep it in this cell.
A7: Business sponsor | B7: TBC | E7: Named individual required before EA approval.
A8: Architecture owner | B8: TBC | E8: Named individual required before EA approval.
A9: Delivery owner | B9: TBC | E9: Named individual required before EA approval.
A10: Estimated cost (USD) | B10: 0
A11: Estimated duration (months) | B11: 0
A12: Hard external deadline
A13: Current status | B13: Proposed
A14: Recommended wave | E14: See '03 Sequencing'.
A15: Basis of estimate | B15: TBC | E15: Cite the document and slide or section.
A17: 2. Weighted impact assessment
A18: Enter 1 to 5 in column B. Anchors are on '01 Scoring Model'. Column C is a link; do not edit it.
A19: Dimension | B19: Score (1-5) | C19: Weight | D19: Weighted | E19: Assessment | F19: Owner | G19: Evidence and basis
A20: Business value | C20: ='01 Scoring Model'!$B$6 -> 0.2 | D20: =IF(B20="","",B20*C20)
A21: Cost optimization and savings | C21: ='01 Scoring Model'!$B$7 -> 0.2 | D21: =IF(B21="","",B21*C21)
A22: Time criticality | C22: ='01 Scoring Model'!$B$8 -> 0.2 | D22: =IF(B22="","",B22*C22)
A23: Risk reduction and resilience | C23: ='01 Scoring Model'!$B$9 -> 0.1 | D23: =IF(B23="","",B23*C23)
A24: Security and compliance | C24: ='01 Scoring Model'!$B$10 -> 0.1 | D24: =IF(B24="","",B24*C24)
A25: Delivery confidence | C25: ='01 Scoring Model'!$B$11 -> 0.1 | D25: =IF(B25="","",B25*C25)
A26: Strategic and architecture alignment | C26: ='01 Scoring Model'!$B$12 -> 0.1 | D26: =IF(B26="","",B26*C26)
A27: Weighted priority score | D27: =IF(COUNT(B20:B26)=0,"",ROUND(SUM(D20:D26),2)) | E27: Out of 5.00. Compare on '02 Portfolio Summary'.
A29: 3. Scope
A30: In scope | E30: Explicitly out of scope
A36: 4. Dependencies
A37: Type | B37: Depends on | E37: Nature of the dependency | F37: Owner | G37: Criticality
A43: 5. Key risks
A44: Risk | B44: Likelihood | C44: Impact | D44: Score | E44: Mitigation | F44: Owner | G44: Response (residual score)
A49: Likelihood times impact, each 1 to 4 (Low, Medium, High, Critical). Red at 9 or above: needs a named owner and a review date. Optional 6th to 8th items per risk: response, residual likelihood, residual impact.
A51: 6. Success KPIs
A52: KPI | B52: Baseline | D52: Target | E52: Measurement source | F52: Measured by
A58: 7. EA governance gates
A59: Gate | B59: Status | E59: Evidence or artefact | F59: Reviewer | G59: Date cleared
A60: Alignment with a named business capability | B60: Not started
A61: Architecture standards compliance | B61: Not started
A62: Security review completed | B62: Not started
A63: Operational ownership defined (named team, not a role) | B63: Not started
...

Sheet P4
A1: P4. <project name>
A2: Enterprise Architecture Impact Matrix
A4: 1. Project profile
A5: Project ID | B5: P4
A6: Project name | E6: Pulled by '02 Portfolio Summary'. Keep it in this cell.
A7: Business sponsor | B7: TBC | E7: Named individual required before EA approval.
A8: Architecture owner | B8: TBC | E8: Named individual required before EA approval.
A9: Delivery owner | B9: TBC | E9: Named individual required before EA approval.
A10: Estimated cost (USD) | B10: 0
A11: Estimated duration (months) | B11: 0
A12: Hard external deadline
A13: Current status | B13: Proposed
A14: Recommended wave | E14: See '03 Sequencing'.
A15: Basis of estimate | B15: TBC | E15: Cite the document and slide or section.
A17: 2. Weighted impact assessment
A18: Enter 1 to 5 in column B. Anchors are on '01 Scoring Model'. Column C is a link; do not edit it.
A19: Dimension | B19: Score (1-5) | C19: Weight | D19: Weighted | E19: Assessment | F19: Owner | G19: Evidence and basis
A20: Business value | C20: ='01 Scoring Model'!$B$6 -> 0.2 | D20: =IF(B20="","",B20*C20)
A21: Cost optimization and savings | C21: ='01 Scoring Model'!$B$7 -> 0.2 | D21: =IF(B21="","",B21*C21)
A22: Time criticality | C22: ='01 Scoring Model'!$B$8 -> 0.2 | D22: =IF(B22="","",B22*C22)
A23: Risk reduction and resilience | C23: ='01 Scoring Model'!$B$9 -> 0.1 | D23: =IF(B23="","",B23*C23)
A24: Security and compliance | C24: ='01 Scoring Model'!$B$10 -> 0.1 | D24: =IF(B24="","",B24*C24)
A25: Delivery confidence | C25: ='01 Scoring Model'!$B$11 -> 0.1 | D25: =IF(B25="","",B25*C25)
A26: Strategic and architecture alignment | C26: ='01 Scoring Model'!$B$12 -> 0.1 | D26: =IF(B26="","",B26*C26)
A27: Weighted priority score | D27: =IF(COUNT(B20:B26)=0,"",ROUND(SUM(D20:D26),2)) | E27: Out of 5.00. Compare on '02 Portfolio Summary'.
A29: 3. Scope
A30: In scope | E30: Explicitly out of scope
A36: 4. Dependencies
A37: Type | B37: Depends on | E37: Nature of the dependency | F37: Owner | G37: Criticality
A43: 5. Key risks
A44: Risk | B44: Likelihood | C44: Impact | D44: Score | E44: Mitigation | F44: Owner | G44: Response (residual score)
A49: Likelihood times impact, each 1 to 4 (Low, Medium, High, Critical). Red at 9 or above: needs a named owner and a review date. Optional 6th to 8th items per risk: response, residual likelihood, residual impact.
A51: 6. Success KPIs
A52: KPI | B52: Baseline | D52: Target | E52: Measurement source | F52: Measured by
A58: 7. EA governance gates
A59: Gate | B59: Status | E59: Evidence or artefact | F59: Reviewer | G59: Date cleared
A60: Alignment with a named business capability | B60: Not started
A61: Architecture standards compliance | B61: Not started
A62: Security review completed | B62: Not started
A63: Operational ownership defined (named team, not a role) | B63: Not started
...

Sheet P5
A1: P5. <project name>
A2: Enterprise Architecture Impact Matrix
A4: 1. Project profile
A5: Project ID | B5: P5
A6: Project name | E6: Pulled by '02 Portfolio Summary'. Keep it in this cell.
A7: Business sponsor | B7: TBC | E7: Named individual required before EA approval.
A8: Architecture owner | B8: TBC | E8: Named individual required before EA approval.
A9: Delivery owner | B9: TBC | E9: Named individual required before EA approval.
A10: Estimated cost (USD) | B10: 0
A11: Estimated duration (months) | B11: 0
A12: Hard external deadline
A13: Current status | B13: Proposed
A14: Recommended wave | E14: See '03 Sequencing'.
A15: Basis of estimate | B15: TBC | E15: Cite the document and slide or section.
A17: 2. Weighted impact assessment
A18: Enter 1 to 5 in column B. Anchors are on '01 Scoring Model'. Column C is a link; do not edit it.
A19: Dimension | B19: Score (1-5) | C19: Weight | D19: Weighted | E19: Assessment | F19: Owner | G19: Evidence and basis
A20: Business value | C20: ='01 Scoring Model'!$B$6 -> 0.2 | D20: =IF(B20="","",B20*C20)
A21: Cost optimization and savings | C21: ='01 Scoring Model'!$B$7 -> 0.2 | D21: =IF(B21="","",B21*C21)
A22: Time criticality | C22: ='01 Scoring Model'!$B$8 -> 0.2 | D22: =IF(B22="","",B22*C22)
A23: Risk reduction and resilience | C23: ='01 Scoring Model'!$B$9 -> 0.1 | D23: =IF(B23="","",B23*C23)
A24: Security and compliance | C24: ='01 Scoring Model'!$B$10 -> 0.1 | D24: =IF(B24="","",B24*C24)
A25: Delivery confidence | C25: ='01 Scoring Model'!$B$11 -> 0.1 | D25: =IF(B25="","",B25*C25)
A26: Strategic and architecture alignment | C26: ='01 Scoring Model'!$B$12 -> 0.1 | D26: =IF(B26="","",B26*C26)
A27: Weighted priority score | D27: =IF(COUNT(B20:B26)=0,"",ROUND(SUM(D20:D26),2)) | E27: Out of 5.00. Compare on '02 Portfolio Summary'.
A29: 3. Scope
A30: In scope | E30: Explicitly out of scope
A36: 4. Dependencies
A37: Type | B37: Depends on | E37: Nature of the dependency | F37: Owner | G37: Criticality
A43: 5. Key risks
A44: Risk | B44: Likelihood | C44: Impact | D44: Score | E44: Mitigation | F44: Owner | G44: Response (residual score)
A49: Likelihood times impact, each 1 to 4 (Low, Medium, High, Critical). Red at 9 or above: needs a named owner and a review date. Optional 6th to 8th items per risk: response, residual likelihood, residual impact.
A51: 6. Success KPIs
A52: KPI | B52: Baseline | D52: Target | E52: Measurement source | F52: Measured by
A58: 7. EA governance gates
A59: Gate | B59: Status | E59: Evidence or artefact | F59: Reviewer | G59: Date cleared
A60: Alignment with a named business capability | B60: Not started
A61: Architecture standards compliance | B61: Not started
A62: Security review completed | B62: Not started
A63: Operational ownership defined (named team, not a role) | B63: Not started
...

Sheet P6
A1: P6. <project name>
A2: Enterprise Architecture Impact Matrix
A4: 1. Project profile
A5: Project ID | B5: P6
A6: Project name | E6: Pulled by '02 Portfolio Summary'. Keep it in this cell.
A7: Business sponsor | B7: TBC | E7: Named individual required before EA approval.
A8: Architecture owner | B8: TBC | E8: Named individual required before EA approval.
A9: Delivery owner | B9: TBC | E9: Named individual required before EA approval.
A10: Estimated cost (USD) | B10: 0
A11: Estimated duration (months) | B11: 0
A12: Hard external deadline
A13: Current status | B13: Proposed
A14: Recommended wave | E14: See '03 Sequencing'.
A15: Basis of estimate | B15: TBC | E15: Cite the document and slide or section.
A17: 2. Weighted impact assessment
A18: Enter 1 to 5 in column B. Anchors are on '01 Scoring Model'. Column C is a link; do not edit it.
A19: Dimension | B19: Score (1-5) | C19: Weight | D19: Weighted | E19: Assessment | F19: Owner | G19: Evidence and basis
A20: Business value | C20: ='01 Scoring Model'!$B$6 -> 0.2 | D20: =IF(B20="","",B20*C20)
A21: Cost optimization and savings | C21: ='01 Scoring Model'!$B$7 -> 0.2 | D21: =IF(B21="","",B21*C21)
A22: Time criticality | C22: ='01 Scoring Model'!$B$8 -> 0.2 | D22: =IF(B22="","",B22*C22)
A23: Risk reduction and resilience | C23: ='01 Scoring Model'!$B$9 -> 0.1 | D23: =IF(B23="","",B23*C23)
A24: Security and compliance | C24: ='01 Scoring Model'!$B$10 -> 0.1 | D24: =IF(B24="","",B24*C24)
A25: Delivery confidence | C25: ='01 Scoring Model'!$B$11 -> 0.1 | D25: =IF(B25="","",B25*C25)
A26: Strategic and architecture alignment | C26: ='01 Scoring Model'!$B$12 -> 0.1 | D26: =IF(B26="","",B26*C26)
A27: Weighted priority score | D27: =IF(COUNT(B20:B26)=0,"",ROUND(SUM(D20:D26),2)) | E27: Out of 5.00. Compare on '02 Portfolio Summary'.
A29: 3. Scope
A30: In scope | E30: Explicitly out of scope
A36: 4. Dependencies
A37: Type | B37: Depends on | E37: Nature of the dependency | F37: Owner | G37: Criticality
A43: 5. Key risks
A44: Risk | B44: Likelihood | C44: Impact | D44: Score | E44: Mitigation | F44: Owner | G44: Response (residual score)
A49: Likelihood times impact, each 1 to 4 (Low, Medium, High, Critical). Red at 9 or above: needs a named owner and a review date. Optional 6th to 8th items per risk: response, residual likelihood, residual impact.
A51: 6. Success KPIs
A52: KPI | B52: Baseline | D52: Target | E52: Measurement source | F52: Measured by
A58: 7. EA governance gates
A59: Gate | B59: Status | E59: Evidence or artefact | F59: Reviewer | G59: Date cleared
A60: Alignment with a named business capability | B60: Not started
A61: Architecture standards compliance | B61: Not started
A62: Security review completed | B62: Not started
A63: Operational ownership defined (named team, not a role) | B63: Not started
...

Sheet P7
A1: P7. <project name>
A2: Enterprise Architecture Impact Matrix
A4: 1. Project profile
A5: Project ID | B5: P7
A6: Project name | E6: Pulled by '02 Portfolio Summary'. Keep it in this cell.
A7: Business sponsor | B7: TBC | E7: Named individual required before EA approval.
A8: Architecture owner | B8: TBC | E8: Named individual required before EA approval.
A9: Delivery owner | B9: TBC | E9: Named individual required before EA approval.
A10: Estimated cost (USD) | B10: 0
A11: Estimated duration (months) | B11: 0
A12: Hard external deadline
A13: Current status | B13: Proposed
A14: Recommended wave | E14: See '03 Sequencing'.
A15: Basis of estimate | B15: TBC | E15: Cite the document and slide or section.
A17: 2. Weighted impact assessment
A18: Enter 1 to 5 in column B. Anchors are on '01 Scoring Model'. Column C is a link; do not edit it.
A19: Dimension | B19: Score (1-5) | C19: Weight | D19: Weighted | E19: Assessment | F19: Owner | G19: Evidence and basis
A20: Business value | C20: ='01 Scoring Model'!$B$6 -> 0.2 | D20: =IF(B20="","",B20*C20)
A21: Cost optimization and savings | C21: ='01 Scoring Model'!$B$7 -> 0.2 | D21: =IF(B21="","",B21*C21)
A22: Time criticality | C22: ='01 Scoring Model'!$B$8 -> 0.2 | D22: =IF(B22="","",B22*C22)
A23: Risk reduction and resilience | C23: ='01 Scoring Model'!$B$9 -> 0.1 | D23: =IF(B23="","",B23*C23)
A24: Security and compliance | C24: ='01 Scoring Model'!$B$10 -> 0.1 | D24: =IF(B24="","",B24*C24)
A25: Delivery confidence | C25: ='01 Scoring Model'!$B$11 -> 0.1 | D25: =IF(B25="","",B25*C25)
A26: Strategic and architecture alignment | C26: ='01 Scoring Model'!$B$12 -> 0.1 | D26: =IF(B26="","",B26*C26)
A27: Weighted priority score | D27: =IF(COUNT(B20:B26)=0,"",ROUND(SUM(D20:D26),2)) | E27: Out of 5.00. Compare on '02 Portfolio Summary'.
A29: 3. Scope
A30: In scope | E30: Explicitly out of scope
A36: 4. Dependencies
A37: Type | B37: Depends on | E37: Nature of the dependency | F37: Owner | G37: Criticality
A43: 5. Key risks
A44: Risk | B44: Likelihood | C44: Impact | D44: Score | E44: Mitigation | F44: Owner | G44: Response (residual score)
A49: Likelihood times impact, each 1 to 4 (Low, Medium, High, Critical). Red at 9 or above: needs a named owner and a review date. Optional 6th to 8th items per risk: response, residual likelihood, residual impact.
A51: 6. Success KPIs
A52: KPI | B52: Baseline | D52: Target | E52: Measurement source | F52: Measured by
A58: 7. EA governance gates
A59: Gate | B59: Status | E59: Evidence or artefact | F59: Reviewer | G59: Date cleared
A60: Alignment with a named business capability | B60: Not started
A61: Architecture standards compliance | B61: Not started
A62: Security review completed | B62: Not started
A63: Operational ownership defined (named team, not a role) | B63: Not started
...

Sheet P8
A1: P8. <project name>
A2: Enterprise Architecture Impact Matrix
A4: 1. Project profile
A5: Project ID | B5: P8
A6: Project name | E6: Pulled by '02 Portfolio Summary'. Keep it in this cell.
A7: Business sponsor | B7: TBC | E7: Named individual required before EA approval.
A8: Architecture owner | B8: TBC | E8: Named individual required before EA approval.
A9: Delivery owner | B9: TBC | E9: Named individual required before EA approval.
A10: Estimated cost (USD) | B10: 0
A11: Estimated duration (months) | B11: 0
A12: Hard external deadline
A13: Current status | B13: Proposed
A14: Recommended wave | E14: See '03 Sequencing'.
A15: Basis of estimate | B15: TBC | E15: Cite the document and slide or section.
A17: 2. Weighted impact assessment
A18: Enter 1 to 5 in column B. Anchors are on '01 Scoring Model'. Column C is a link; do not edit it.
A19: Dimension | B19: Score (1-5) | C19: Weight | D19: Weighted | E19: Assessment | F19: Owner | G19: Evidence and basis
A20: Business value | C20: ='01 Scoring Model'!$B$6 -> 0.2 | D20: =IF(B20="","",B20*C20)
A21: Cost optimization and savings | C21: ='01 Scoring Model'!$B$7 -> 0.2 | D21: =IF(B21="","",B21*C21)
A22: Time criticality | C22: ='01 Scoring Model'!$B$8 -> 0.2 | D22: =IF(B22="","",B22*C22)
A23: Risk reduction and resilience | C23: ='01 Scoring Model'!$B$9 -> 0.1 | D23: =IF(B23="","",B23*C23)
A24: Security and compliance | C24: ='01 Scoring Model'!$B$10 -> 0.1 | D24: =IF(B24="","",B24*C24)
A25: Delivery confidence | C25: ='01 Scoring Model'!$B$11 -> 0.1 | D25: =IF(B25="","",B25*C25)
A26: Strategic and architecture alignment | C26: ='01 Scoring Model'!$B$12 -> 0.1 | D26: =IF(B26="","",B26*C26)
A27: Weighted priority score | D27: =IF(COUNT(B20:B26)=0,"",ROUND(SUM(D20:D26),2)) | E27: Out of 5.00. Compare on '02 Portfolio Summary'.
A29: 3. Scope
A30: In scope | E30: Explicitly out of scope
A36: 4. Dependencies
A37: Type | B37: Depends on | E37: Nature of the dependency | F37: Owner | G37: Criticality
A43: 5. Key risks
A44: Risk | B44: Likelihood | C44: Impact | D44: Score | E44: Mitigation | F44: Owner | G44: Response (residual score)
A49: Likelihood times impact, each 1 to 4 (Low, Medium, High, Critical). Red at 9 or above: needs a named owner and a review date. Optional 6th to 8th items per risk: response, residual likelihood, residual impact.
A51: 6. Success KPIs
A52: KPI | B52: Baseline | D52: Target | E52: Measurement source | F52: Measured by
A58: 7. EA governance gates
A59: Gate | B59: Status | E59: Evidence or artefact | F59: Reviewer | G59: Date cleared
A60: Alignment with a named business capability | B60: Not started
A61: Architecture standards compliance | B61: Not started
A62: Security review completed | B62: Not started
A63: Operational ownership defined (named team, not a role) | B63: Not started
...
